2023-12-03 11:45:37,740 INFO    MainThread:23368 [wandb_setup.py:_flush():76] Current SDK version is 0.16.0
2023-12-03 11:45:37,740 INFO    MainThread:23368 [wandb_setup.py:_flush():76] Configure stats pid to 23368
2023-12-03 11:45:37,740 INFO    MainThread:23368 [wandb_setup.py:_flush():76] Loading settings from C:\Users\theho\.config\wandb\settings
2023-12-03 11:45:37,740 INFO    MainThread:23368 [wandb_setup.py:_flush():76] Loading settings from C:\Users\theho\git_AI_Application_Practice\07.Olympic\wandb\settings
2023-12-03 11:45:37,740 INFO    MainThread:23368 [wandb_setup.py:_flush():76] Loading settings from environment variables: {}
2023-12-03 11:45:37,740 INFO    MainThread:23368 [wandb_setup.py:_flush():76] Applying setup settings: {'_disable_service': False}
2023-12-03 11:45:37,741 INFO    MainThread:23368 [wandb_setup.py:_flush():76] Inferring run settings from compute environment: {'program_relpath': '07.Olympic\\f_ppo_train.py', 'program_abspath': 'C:\\Users\\theho\\git_AI_Application_Practice\\07.Olympic\\f_ppo_train.py', 'program': 'C:\\Users\\theho\\git_AI_Application_Practice\\07.Olympic\\f_ppo_train.py'}
2023-12-03 11:45:37,741 INFO    MainThread:23368 [wandb_init.py:_log_setup():524] Logging user logs to C:\Users\theho\git_AI_Application_Practice\07.Olympic\wandb\run-20231203_114537-k8khty7l\logs\debug.log
2023-12-03 11:45:37,741 INFO    MainThread:23368 [wandb_init.py:_log_setup():525] Logging internal logs to C:\Users\theho\git_AI_Application_Practice\07.Olympic\wandb\run-20231203_114537-k8khty7l\logs\debug-internal.log
2023-12-03 11:45:37,741 INFO    MainThread:23368 [wandb_init.py:init():564] calling init triggers
2023-12-03 11:45:37,741 INFO    MainThread:23368 [wandb_init.py:init():571] wandb.init called with sweep_config: {}
config: {}
2023-12-03 11:45:37,741 INFO    MainThread:23368 [wandb_init.py:init():614] starting backend
2023-12-03 11:45:37,742 INFO    MainThread:23368 [wandb_init.py:init():618] setting up manager
2023-12-03 11:45:37,747 INFO    MainThread:23368 [backend.py:_multiprocessing_setup():105] multiprocessing start_methods=spawn, using: spawn
2023-12-03 11:45:37,756 INFO    MainThread:23368 [wandb_init.py:init():624] backend started and connected
2023-12-03 11:45:37,765 INFO    MainThread:23368 [wandb_init.py:init():716] updated telemetry
2023-12-03 11:45:37,889 INFO    MainThread:23368 [wandb_init.py:init():749] communicating run to backend with 90.0 second timeout
2023-12-03 11:46:37,635 INFO    Thread-9 (wrapped_target):23368 [retry.py:__call__():172] Retry attempt failed:
Traceback (most recent call last):
  File "C:\Users\theho\anaconda3\envs\AI_Lecture\lib\site-packages\urllib3\connectionpool.py", line 537, in _make_request
    response = conn.getresponse()
  File "C:\Users\theho\anaconda3\envs\AI_Lecture\lib\site-packages\urllib3\connection.py", line 461, in getresponse
    httplib_response = super().getresponse()
  File "C:\Users\theho\anaconda3\envs\AI_Lecture\lib\http\client.py", line 1375, in getresponse
    response.begin()
  File "C:\Users\theho\anaconda3\envs\AI_Lecture\lib\http\client.py", line 318, in begin
    version, status, reason = self._read_status()
  File "C:\Users\theho\anaconda3\envs\AI_Lecture\lib\http\client.py", line 279, in _read_status
    line = str(self.fp.readline(_MAXLINE + 1), "iso-8859-1")
  File "C:\Users\theho\anaconda3\envs\AI_Lecture\lib\socket.py", line 705, in readinto
    return self._sock.recv_into(b)
  File "C:\Users\theho\anaconda3\envs\AI_Lecture\lib\ssl.py", line 1307, in recv_into
    return self.read(nbytes, buffer)
  File "C:\Users\theho\anaconda3\envs\AI_Lecture\lib\ssl.py", line 1163, in read
    return self._sslobj.read(len, buffer)
TimeoutError: The read operation timed out

The above exception was the direct cause of the following exception:

Traceback (most recent call last):
  File "C:\Users\theho\anaconda3\envs\AI_Lecture\lib\site-packages\requests\adapters.py", line 486, in send
    resp = conn.urlopen(
  File "C:\Users\theho\anaconda3\envs\AI_Lecture\lib\site-packages\urllib3\connectionpool.py", line 845, in urlopen
    retries = retries.increment(
  File "C:\Users\theho\anaconda3\envs\AI_Lecture\lib\site-packages\urllib3\util\retry.py", line 470, in increment
    raise reraise(type(error), error, _stacktrace)
  File "C:\Users\theho\anaconda3\envs\AI_Lecture\lib\site-packages\urllib3\util\util.py", line 39, in reraise
    raise value
  File "C:\Users\theho\anaconda3\envs\AI_Lecture\lib\site-packages\urllib3\connectionpool.py", line 791, in urlopen
    response = self._make_request(
  File "C:\Users\theho\anaconda3\envs\AI_Lecture\lib\site-packages\urllib3\connectionpool.py", line 539, in _make_request
    self._raise_timeout(err=e, url=url, timeout_value=read_timeout)
  File "C:\Users\theho\anaconda3\envs\AI_Lecture\lib\site-packages\urllib3\connectionpool.py", line 371, in _raise_timeout
    raise ReadTimeoutError(
urllib3.exceptions.ReadTimeoutError: HTTPSConnectionPool(host='api.wandb.ai', port=443): Read timed out. (read timeout=20)

During handling of the above exception, another exception occurred:

Traceback (most recent call last):
  File "C:\Users\theho\anaconda3\envs\AI_Lecture\lib\site-packages\wandb\sdk\lib\retry.py", line 131, in __call__
    result = self._call_fn(*args, **kwargs)
  File "C:\Users\theho\anaconda3\envs\AI_Lecture\lib\site-packages\wandb\sdk\internal\internal_api.py", line 366, in execute
    return self.client.execute(*args, **kwargs)  # type: ignore
  File "C:\Users\theho\anaconda3\envs\AI_Lecture\lib\site-packages\wandb\vendor\gql-0.2.0\wandb_gql\client.py", line 52, in execute
    result = self._get_result(document, *args, **kwargs)
  File "C:\Users\theho\anaconda3\envs\AI_Lecture\lib\site-packages\wandb\vendor\gql-0.2.0\wandb_gql\client.py", line 60, in _get_result
    return self.transport.execute(document, *args, **kwargs)
  File "C:\Users\theho\anaconda3\envs\AI_Lecture\lib\site-packages\wandb\sdk\lib\gql_request.py", line 58, in execute
    request = self.session.post(self.url, **post_args)
  File "C:\Users\theho\anaconda3\envs\AI_Lecture\lib\site-packages\requests\sessions.py", line 637, in post
    return self.request("POST", url, data=data, json=json, **kwargs)
  File "C:\Users\theho\anaconda3\envs\AI_Lecture\lib\site-packages\requests\sessions.py", line 589, in request
    resp = self.send(prep, **send_kwargs)
  File "C:\Users\theho\anaconda3\envs\AI_Lecture\lib\site-packages\requests\sessions.py", line 703, in send
    r = adapter.send(request, **kwargs)
  File "C:\Users\theho\anaconda3\envs\AI_Lecture\lib\site-packages\requests\adapters.py", line 532, in send
    raise ReadTimeout(e, request=request)
requests.exceptions.ReadTimeout: HTTPSConnectionPool(host='api.wandb.ai', port=443): Read timed out. (read timeout=20)
2023-12-03 11:47:07,922 ERROR   MainThread:23368 [wandb_init.py:init():775] encountered error: Run initialization has timed out after 90.0 sec. 
Please refer to the documentation for additional information: https://docs.wandb.ai/guides/track/tracking-faq#initstarterror-error-communicating-with-wandb-process-
2023-12-03 11:47:08,453 ERROR   MainThread:23368 [wandb_init.py:init():1184] Run initialization has timed out after 90.0 sec. 
Please refer to the documentation for additional information: https://docs.wandb.ai/guides/track/tracking-faq#initstarterror-error-communicating-with-wandb-process-
Traceback (most recent call last):
  File "C:\Users\theho\anaconda3\envs\AI_Lecture\lib\site-packages\wandb\sdk\wandb_init.py", line 1166, in init
    run = wi.init()
  File "C:\Users\theho\anaconda3\envs\AI_Lecture\lib\site-packages\wandb\sdk\wandb_init.py", line 781, in init
    raise error
wandb.errors.CommError: Run initialization has timed out after 90.0 sec. 
Please refer to the documentation for additional information: https://docs.wandb.ai/guides/track/tracking-faq#initstarterror-error-communicating-with-wandb-process-
2023-12-03 11:47:09,460 WARNING MsgRouterThr:23368 [router.py:message_loop():77] message_loop has been closed
